Workbook

Sheet Atualização
A1: Data de Atualização: | B1: 45883
A2: Saldo Atual: | B2: =-3409.29+7437.76 -> 4028.47

Sheet Previsão de orçamentária
A1: Débitos | B1: 45748 | C1: =B1+31 -> 45779 | D1: =C1+31 -> 45810 | E1: =D1+31 -> 45841 | F1: =E1+31 -> 45872 | G1: =F1+31 -> 45903 | H1: =G1+31 -> 45934 | I1: =H1+31 -> 45965 | J1: =I1+31 -> 45996 | ... M1: =L1+31 -> 46089
A2: Salário | B2: 0 | C2: 0 | D2: 0 | E2: 0 | F2: 0 | G2: =15635+450-(12000/5)-(3757.83/5) -> 12933.434 | H2: =15635+450-(12000/5)-(3757.83/5) -> 12933.434 | I2: =15635+450-(3757.83/5) -> 15333.434 | J2: =15635+450-(3757.83/5) -> 15333.434 | K2: =15635-(3757.83/5) -> 14883.434 | L2: =15635 -> 15635 | M2: =15635 -> 15635
A3: Juros Ch Especial | B3: 0 | C3: 0 | D3: 0 | E3: 0 | F3: 0 | G3: 0 | H3: 0 | I3: 0 | J3: 0 | K3: 0 | L3: 0 | M3: 0
A4: Saldo inicio mês | B4: 0 | C4: 0 | D4: 0 | E4: 0 | F4: =Atualização!B2 -> 4028.47 | G4: =G2-G3+F21 -> 16961.904 | H4: =H2-H3+G21 -> 14683.27 | I4: =I2-I3+H21 -> 16410.704 | J4: =J2-J3+I21 -> 18938.138 | K4: =K2-K3+J21 -> 20015.572 | L4: =L2-L3+K21 -> 21844.572 | M4: =M2-M3+L21 -> 23673.572
A5: Emprestimo BB | B5: 0 | C5: 0 | D5: 0 | E5: 0 | F5: 0 | G5: 0 | H5: 0 | I5: 0 | J5: 0 | K5: 0 | L5: 0 | M5: 0
A6: Emprestimo REAL | B6: 0 | C6: 0 | D6: 0 | E6: 0 | F6: 0 | G6: 0 | H6: 0 | I6: 0 | J6: 0 | K6: 0 | L6: 0 | M6: 0
A7: Poupança - Rogério | B7: 0 | C7: 0 | D7: 0 | E7: 0 | F7: 0 | G7: 5000 | H7: 5000 | I7: 5000 | J7: 6000 | K7: 6000 | L7: 6000 | M7: 6000
A8: Condomínio | B8: 0 | C8: 0 | D8: 0 | E8: 0 | F8: 0 | G8: 450 | H8: 450 | I8: 450 | J8: 450 | K8: 450 | L8: 450 | M8: 450
A9: Ingles | B9: 0 | C9: 0 | D9: 0 | E9: 0 | F9: 0 | G9: 0 | H9: 0 | I9: 0 | J9: 0 | K9: 0 | L9: 0 | M9: 0
A10: bb preve | B10: 0 | C10: 0 | D10: 0 | E10: 0 | F10: 0 | G10: 0 | H10: 0 | I10: 0 | J10: 0 | K10: 0 | L10: 0 | M10: 0
A11: Casa Bsb | B11: 0 | C11: 0 | D11: 0 | E11: 0 | F11: 0 | G11: 600 | H11: 600 | I11: 600 | J11: 600 | K11: 600 | L11: 600 | M11: 600
A12: Cartão | B12: 0 | C12: 0 | D12: =0 -> 0 | E12: 0 | F12: =0 -> 0 | G12: ='XP 1451 Vence dia 01'!T29+'BB Master 5077 Venc dia 02'!T30+'BB VISA 4356 - Vence dia 12 '!T29+'Santander 9674 Vende dia 22'!T29+'BB Petrobras 8392 Vence dia 22'!T31 -> 6242.1379 | H12: ='XP 1451 Vence dia 01'!W29+'BB Master 5077 Venc dia 02'!W30+'BB VISA 4356 - Vence dia 12 '!W29+'Santander 9674 Vende dia 22'!W29+'BB Petrobras 8392 Vence dia 22'!W31 -> 2038.5857 | I12: ='XP 1451 Vence dia 01'!Z29+'BB Master 5077 Venc dia 02'!Z30+'BB VISA 4356 - Vence dia 12 '!Z29+'Santander 9674 Vende dia 22'!Z29+'BB Petrobras 8392 Vence dia 22'!Z31 -> 1796.5857 | J12: ='XP 1451 Vence dia 01'!AC29+'BB Master 5077 Venc dia 02'!AC30+'BB VISA 4356 - Vence dia 12 '!AC29+'Santander 9674 Vende dia 22'!AC29+'BB Petrobras 8392 Vence dia 22'!AC31 -> 284.04 | K12: ='XP 1451 Vence dia 01'!AF29+'BB Master 5077 Venc dia 02'!AF30+'BB VISA 4356 - Vence dia 12 '!AF29+'Santander 9674 Vende dia 22'!AF29+'BB Petrobras 8392 Vence dia 22'!AF31 -> 265.14 | L12: ='XP 1451 Vence dia 01'!AI29+'BB Master 5077 Venc dia 02'!AI30+'BB VISA 4356 - Vence dia 12 '!AI29+'Santander 9674 Vende dia 22'!AI29+'BB Petrobras 8392 Vence dia 22'!AI31 -> 265.14 | M12: ='XP 1451 Vence dia 01'!AL29+'BB Master 5077 Venc dia 02'!AL30+'BB VISA 4356 - Vence dia 12 '!AL29+'Santander 9674 Vende dia 22'!AL29+'BB Petrobras 8392 Vence dia 22'!AL31 -> 265.14
A13: Outros (NADART) / Ingles | B13: 0 | C13: 0 | D13: 0 | E13: 0 | F13: 0 | G13: 0 | H13: 0 | I13: 0 | J13: 0 | K13: 0 | L13: 0 | M13: 0
A14: Cartão - previsão | B14: 0 | C14: 0 | D14: 0 | E14: 0 | F14: 0 | G14: =IF(5000-G12>0,5000-G12,0) -> 0 | H14: =IF(5000-H12>0,5000-H12,0) -> 2961.4143 | I14: =IF(5000-I12>0,5000-I12,0) -> 3203.4143 | J14: =IF(5000-J12>0,5000-J12,0) -> 4715.96 | K14: =IF(5000-K12>0,5000-K12,0) -> 4734.86 | L14: =IF(5000-L12>0,5000-L12,0) -> 4734.86 | M14: =IF(5000-M12>0,5000-M12,0) -> 4734.86
A15: Advogado - Incorporação | B15: 0 | C15: 0 | D15: 0 | E15: 0 | F15: 0 | G15: 0 | H15: 0 | I15: 0 | J15: 0 | K15: 0 | L15: 0 | M15: 0
A16: Investimento | B16: 0 | C16: 0 | D16: 0 | E16: 0 | F16: 0 | G16: 0 | H16: 0 | I16: 0 | J16: 0 | K16: 0 | L16: 0 | M16: 0
A17: Pagamentos | B17: 0 | C17: 0 | D17: 0 | E17: 0 | F17: 0 | G17: =1512+800 -> 2312 | H17: =1512+800 -> 2312 | I17: 1512 | J17: =I17 -> 1512 | K17: =J17 -> 1512 | L17: =K17 -> 1512 | M17: =L17 -> 1512
A18: Outros (IPTU/IPVA/Seguro/Saude) | B18: 0 | C18: 0 | D18: 0 | E18: 0 | F18: 0 | G18: =363.93+244 -> 607.93 | H18: =244 -> 244 | I18: =244 -> 244 | J18: =244 -> 244 | K18: =244 -> 244 | L18: =244 -> 244 | M18: =244 -> 244
A19: Complementares | B19: 0 | C19: 0 | D19: 0 | E19: 0 | F19: =E19 -> 0 | G19: =F19 -> 0 | H19: =G19 -> 0 | I19: =H19 -> 0 | J19: =I19 -> 0 | K19: =J19 -> 0 | L19: =K19 -> 0 | M19: =L19 -> 0
A20: Total | B20: =SUM(B5:B19) -> 0 | C20: =SUM(C5:C19) -> 0 | D20: =SUM(D5:D19) -> 0 | E20: =SUM(E5:E19) -> 0 | F20: =SUM(F5:F19) -> 0 | G20: =SUM(G5:G19) -> 15212.068 | H20: =SUM(H5:H19) -> 13606 | I20: =SUM(I5:I19) -> 12806 | ... M20: =SUM(M5:M19) -> 13806
A21: Saldo Final do Mês | B21: =B4-B20 -> 0 | C21: =C4-C20 -> 0 | D21: =D4-D20 -> 0 | E21: =E4-E20 -> 0 | F21: =F4-F20 -> 4028.47 | G21: =G4-G20 -> 1749.8361 | H21: =H4-H20 -> 1077.2701 | I21: =I4-I20 -> 3604.7041 | ... M21: =M4-M20 -> 9867.5721
A22: Somatorio verde | B22: =B24+B25+B26+B27+B28+B16-B23 -> 80421.81 | C22: =C24+C25+C26+C27+C28+C16-C23 -> 80662.12 | D22: =D24+D25+D26+D27+D28+D16-D23 -> 80881.28 | E22: =E24+E25+E26+E27+E28+E16-E23 -> 89256.65 | F22: =F24+F25+F26+F27+F28+F16-F23 -> 91377.49 | G22: =G24+G25+G26+G27+G28+G16-G23 -> 96377.49 | H22: =H24+H25+H26+H27+H28+H16-H23 -> 101377.49 | I22: =I24+I25+I26+I27+I28+I16-I23 -> 106377.49 | ... M22: =M24+M25+M26+M27+M28+M16-M23 -> 130377.49
B23: 0 | C23: 0 | D23: 0 | E23: 0 | F23: 0 | G23: 0 | H23: 0 | I23: 0 | J23: 0 | K23: 0 | L23: 0 | M23: 0
A24: Santander | B24: 20097.95 | C24: 20130.66 | D24: =C24+D7 -> 20130.66 | E24: 23363.5 | F24: =E24+F7 -> 23363.5 | G24: =F24+G7 -> 28363.5 | H24: =G24+H7 -> 33363.5 | I24: =H24+I7 -> 38363.5 | J24: =I24+J7 -> 44363.5 | K24: =J24+K7 -> 50363.5 | L24: =K24+L7 -> 56363.5 | M24: =L24+M7 -> 62363.5
A25: XP Investimentos | B25: 16477.15 | C25: =B25 -> 16477.15 | D25: =C25 -> 16477.15 | E25: =D25 -> 16477.15 | F25: =828.06+17135.94 -> 17964 | G25: =F25 -> 17964 | H25: =G25 -> 17964 | I25: =H25 -> 17964 | J25: =I25 -> 17964 | K25: =J25 -> 17964 | L25: =K25 -> 17964 | M25: =L25 -> 17964
A26: CDI | B26: 7628.04 | C26: 7693.8 | D26: =C26 -> 7693.8 | E26: =D26 -> 7693.8 | F26: 7891.56 | G26: =F26 -> 7891.56 | H26: =G26 -> 7891.56 | I26: =H26 -> 7891.56 | J26: =I26 -> 7891.56 | K26: =J26 -> 7891.56 | L26: =K26 -> 7891.56 | M26: =L26 -> 7891.56
A27: Poupança - Rogério (51) | B27: 18000 | C27: =B27 -> 18000 | D27: 18116.19 | E27: 18238.04 | F27: 18360.74 | G27: =F27 -> 18360.74 | H27: =G27 -> 18360.74 | I27: =H27 -> 18360.74 | J27: =I27 -> 18360.74 | K27: =J27 -> 18360.74 | L27: =K27 -> 18360.74 | M27: =L27 -> 18360.74
A28: Poupança - Rogério(96) | B28: 18218.67 | C28: 18360.51 | D28: 18463.48 | E28: 23484.16 | F28: 23797.69 | G28: =F28 -> 23797.69 | H28: =G28 -> 23797.69 | I28: =H28 -> 23797.69 | J28: =I28 -> 23797.69 | K28: =J28 -> 23797.69 | L28: =K28 -> 23797.69 | M28: =L28 -> 23797.69
B29: =B22+B21 -> 80421.81 | C29: =C22+C21 -> 80662.12 | D29: =D22+D21 -> 80881.28 | E29: =E22+E21 -> 89256.65 | F29: =F22+F21 -> 95405.96 | G29: =G22+G21 -> 98127.326 | H29: =H22+H21 -> 102454.76 | I29: =I22+I21 -> 109982.19 | ... M29: =M22+M21 -> 140245.06
A32: Previdência Privada
A34: Aplicações

Sheet XP 1451  Vence dia 01
A1: Item | B1: Valor | C1: 45748 | F1: =C1+31 -> 45779 | I1: =F1+31 -> 45810 | L1: =I1+31 -> 45841 | O1: =L1+31 -> 45872 | R1: =O1+31 -> 45903 | U1: =R1+31 -> 45934 | X1: =U1+31 -> 45965 | AA1: =X1+31 -> 45996 | AD1: =AA1+31 -> 46027 | AG1: =AD1+31 -> 46058 | AJ1: =AG1+31 -> 46089
A2: Condomínio | C2: Data | D2: Descrição | E2: Valor | F2: Data | G2: Descrição | H2: Valor | I2: Data | J2: Descrição | K2: Valor | L2: Data | M2: Descrição | N2: Valor | O2: Data | P2: Descrição | Q2: Valor | R2: Data | S2: Descrição | T2: Valor | U2: Data | V2: Descrição | W2: Valor | X2: Data | Y2: Descrição | Z2: Valor | AA2: Data | AB2: Descrição | AC2: Valor | AD2: Data | AE2: Descrição | AF2: Valor | AG2: Data | AH2: Descrição | AI2: Valor | AJ2: Data | AK2: Descrição | AL2: Valor
A3: Brasília | B3: 0 | C3: 45673 | D3: Seguro Kicks(3/10) | E3: =3048.89/10 -> 304.889 | F3: 45673 | G3: Seguro Kicks(4/10) | H3: =3048.89/10 -> 304.889 | I3: 45673 | J3: Seguro Kicks(5/10) | K3: =3048.89/10 -> 304.889 | L3: 45673 | M3: Seguro Kicks(6/10) | N3: =3048.89/10 -> 304.889 | O3: 45673 | P3: Seguro Kicks(7/10) | Q3: =3048.89/10 -> 304.889 | R3: 45673 | S3: Seguro Kicks(8/10) | T3: =3048.89/10 -> 304.889 | U3: 45673 | V3: Seguro Kicks(9/10) | W3: =3048.89/10 -> 304.889 | X3: 45673 | Y3: Seguro Kicks(10/10) | Z3: =3048.89/10 -> 304.889
A4: Caldas | B4: 0 | C4: 45712 | D4: Armarinho | E4: 83 | F4: 45767 | G4: Localiza | H4: =1287.16/2 -> 643.58 | I4: 45767 | J4: Localiza | K4: =1287.16/2 -> 643.58 | L4: 45801 | M4: D. Xepa | N4: 21.57 | O4: 45803 | P4: DMCell(2/3) | Q4: =169/3 -> 56.333333 | R4: 45803 | S4: DMCell(2/3) | T4: =169/3 -> 56.333333 | U4: 45803 | V4: DMCell(3/3) | W4: =169/3 -> 56.333333 | X4: 45881 | Y4: CAOA(3/3) | Z4: =983.3/3 -> 327.76667
A5: Cartão | B5: 1242 | C5: 45713 | D5: Xeus | E5: 45 | L5: 45802 | M5: Acai Point | N5: 36.7 | O5: 45803 | P5: Otto Glasses (2/3) | Q5: =287/3 -> 95.666667 | R5: 45803 | S5: Otto Glasses (2/3) | T5: =287/3 -> 95.666667 | U5: 45803 | V5: Otto Glasses (3/3) | W5: =287/3 -> 95.666667
A6: Capitalização | B6: 0 | C6: 45712 | D6: Sesc | E6: 28.11 | L6: 45802 | M6: Tassarinha | N6: 37.97 | R6: 45881 | S6: CAOA(1/3) | T6: =983.3/3 -> 327.76667 | U6: 45881 | V6: CAOA(2/3) | W6: =983.3/3 -> 327.76667
A7: Seguro | B7: 0 | C7: 45712 | D7: Chocomilk | E7: 103.96 | L7: 45803 | M7: DMCell(1/3) | N7: =169/3 -> 56.333333
A8: Emprestimo | B8: 0 | C8: 45711 | D8: Acai | E8: 11 | L8: 45803 | M8: Posto | N8: 115
A9: TED | B9: 0 | C9: 45710 | D9: Drogaria | E9: 23 | L9: 45803 | M9: Jeriva | N9: 126.97
A10: Mensalidade | B10: 0 | C10: 45713 | D10: Ultrabox | E10: 27.93 | L10: 45803 | M10: Posto | N10: 118.23
A11: Tarifa de conta | B11: 0 | C11: 45715 | D11: Kaely | E11: 37.96 | L11: 45803 | M11: Otto Glasses (1/3) | N11: =287/3 -> 95.666667
A12: Extra | B12: 0 | C12: 45719 | D12: Posto | E12: 104.53 | L12: 45806 | M12: Pizza | N12: 221.47
A13: Total | B13: =SUM(B2:B12) -> 1242 | C13: 45715 | D13: Entre trevos | E13: 87.83 | L13: 45806 | M13: Leroy merlim | N13: 174.9
C14: 45715 | D14: Posto | E14: 231.37
A15: Saldo | B15: 31 | C15: 45714 | D15: Bonanza | E15: 39.18
A16: Transferir | B16: =B15-B13 -> -1211 | C16: 45714 | D16: Debora albes | E16: 74
C17: 45713 | D17: SESC | E17: 15.84
C18: 45714 | D18: Japao | E18: 18.9
C19: 45717 | D19: Levmais | E19: 8.68
C20: 45716 | D20: Weley | E20: 170
C21: 45716 | D21: D.Xepa | E21: 88.49
C22: 45715 | D22: Vanessa | E22: 27
C23: 45715 | D23: Posto | E23: 154.43
E29: =SUM(E2:E28) -> 1685.099 | H29: =SUM(H2:H28) -> 948.469 | K29: =SUM(K2:K28) -> 948.469 | N29: =SUM(N2:N28) -> 1309.699 | Q29: =SUM(Q2:Q28) -> 456.889 | T29: =SUM(T2:T28) -> 784.65567 | W29: =SUM(W2:W28) -> 784.65567 | Z29: =SUM(Z2:Z28) -> 632.65567 | AC29: =SUM(AC2:AC28) -> 0 | AF29: =SUM(AF2:AF28) -> 0 | AI29: =SUM(AI2:AI28) -> 0 | AL29: =SUM(AL2:AL28) -> 0

Sheet BB Master  5077 Venc dia 02
A1: Item | B1: Valor | C1: 45748 | F1: =C1+31 -> 45779 | I1: =F1+31 -> 45810 | L1: =I1+31 -> 45841 | O1: =L1+31 -> 45872 | R1: =O1+31 -> 45903 | U1: =R1+31 -> 45934 | X1: =U1+31 -> 45965 | AA1: =X1+31 -> 45996 | AD1: =AA1+31 -> 46027 | AG1: =AD1+31 -> 46058 | AJ1: =AG1+31 -> 46089
A2: Condomínio | C2: Data | D2: Descrição | E2: Valor | F2: Data | G2: Descrição | H2: Valor | I2: Data | J2: Descrição | K2: Valor | L2: Data | M2: Descrição | N2: Valor | O2: Data | P2: Descrição | Q2: Valor | R2: Data | S2: Descrição | T2: Valor | U2: Data | V2: Descrição | W2: Valor | X2: Data | Y2: Descrição | Z2: Valor | AA2: Data | AB2: Descrição | AC2: Valor | AD2: Data | AE2: Descrição | AF2: Valor | AG2: Data | AH2: Descrição | AI2: Valor | AJ2: Data | AK2: Descrição | AL2: Valor
A3: Brasília | B3: 0 | C3: =C1 -> 45748 | D3: PROTECAO OURO | E3: 3 | F3: =F1 -> 45779 | G3: PROTECAO OURO | H3: 3 | I3: =I1 -> 45810 | J3: PROTECAO OURO | K3: 3 | L3: =L1 -> 45841 | M3: PROTECAO OURO | N3: 3 | O3: 45498 | P3: Franquia Carro Tiggo (12/12) | Q3: 69.9 | R3: =R1 -> 45903 | S3: PROTECAO OURO | T3: 3 | U3: =U1 -> 45934 | V3: PROTECAO OURO | W3: 3 | X3: =X1 -> 45965 | Y3: PROTECAO OURO | Z3: 3 | AA3: =AA1 -> 45996 | AB3: PROTECAO OURO | AC3: 3 | AD3: =AD1 -> 46027 | AE3: PROTECAO OURO | AF3: 3 | AG3: =AG1 -> 46058 | AH3: PROTECAO OURO | AI3: 3 | AJ3: =AJ1 -> 46089 | AK3: PROTECAO OURO | AL3: 3
A4: Caldas | B4: 0 | C4: 45498 | D4: Franquia Carro Tiggo (8/12) | E4: 69.9 | F4: 45498 | G4: Franquia Carro Tiggo (9/12) | H4: 69.9 | I4: 45498 | J4: Franquia Carro Tiggo (10/12) | K4: 69.9 | L4: 45498 | M4: Franquia Carro Tiggo (11/12) | N4: 69.9 | O4: 45541 | P4: Amazon | Q4: 19.9 | R4: 45544 | S4: Odonto Correios | T4: 80 | U4: 45544 | V4: Odonto Correios | W4: 80 | X4: 45544 | Y4: Odonto Correios | Z4: 80 | AA4: 45545 | AB4: Odonto Correios | AC4: 80 | AD4: 45546 | AE4: Odonto Correios | AF4: 80 | AG4: 45547 | AH4: Odonto Correios | AI4: 80 | AJ4: 45548 | AK4: Odonto Correios | AL4: 80
A5: Cartão | C5: 45541 | D5: Amazon | E5: 19.9 | F5: 45541 | G5: Amazon | H5: 19.9 | I5: 45541 | J5: Amazon | K5: 19.9 | L5: 45541 | M5: Amazon | N5: 19.9 | O5: 45544 | P5: Odonto Correios | Q5: 80 | R5: 45835 | S5: France Car (2/4) | T5: =830/4 -> 207.5 | U5: 45835 | V5: France Car (3/4) | W5: =830/4 -> 207.5 | X5: 45835 | Y5: France Car (4/4) | Z5: =830/4 -> 207.5
A6: Capitalização | B6: 0 | C6: 45544 | D6: Odonto Correios | E6: 80 | F6: 45544 | G6: Odonto Correios | H6: 80 | I6: 45544 | J6: Odonto Correios | K6: 80 | L6: 45544 | M6: Odonto Correios | N6: 80 | O6: 45829 | P6: Agropet | Q6: 59.9 | R6: 45862 | S6: Posto | T6: 100 | U6: 45861 | V6: Portas Caldas (2/3) | W6: =930/3 -> 310 | X6: 45861 | Y6: Portas Caldas (3/3) | Z6: =930/3 -> 310
A7: Seguro | B7: 0 | C7: 45623 | D7: Home Ceel(4/4) | E7: =1050/4 -> 262.5 | I7: 45766 | J7: Bonanza | K7: 15.37 | L7: 45775 | M7: Case mania(1/2) | N7: =150/2 -> 75 | O7: 45830 | P7: Bellavia | Q7: 19.89 | R7: 45861 | S7: Portas Caldas (1/3) | T7: =930/3 -> 310 | U7: 45867 | V7: Drogaria (2/3) | W7: =407.37/3 -> 135.79 | X7: 45867 | Y7: Drogaria (3/3) | Z7: =407.37/3 -> 135.79
A8: Emprestimo | B8: 0 | C8: 45710 | D8: Posto | E8: 213.94 | I8: 45765 | J8: Drogaria | K8: 25 | O8: 45830 | P8: Temperus restaurante | Q8: 72.47 | R8: 45862 | S8: Posto | T8: 134.4
A9: TED | B9: 0 | C9: 45710 | D9: Leroy Merlim | E9: 20.34 | I9: 45765 | J9: Dia a dia | K9: 155.09 | O9: 45830 | P9: Golfo importação | Q9: 9.99 | R9: 45862 | S9: Liliany | T9: 31
A10: Mensalidade | B10: 0 | I10: 45766 | J10: Americanas | K10: 30.98 | O10: 45830 | P10: Castelo forte | Q10: 14.9 | R10: 45857 | S10: Ivan | T10: 30
A11: Tarifa de conta | B11: 0 | I11: 45769 | J11: Mercado livre *lampadas | K11: 132 | O11: 45832 | P11: casa de cachorro | Q11: 90 | R11: 45866 | S11: Casa de cachorro | T11: 40
A12: Extra | B12: 0 | I12: 45768 | J12: Almoco | K12: 102 | O12: 45833 | P12: Almoço | Q12: 27 | R12: 45865 | S12: Serra | T12: 45.5
A13: Total | B13: =SUM(B2:B12) -> 0 | I13: 45767 | J13: Mercado Barra | K13: 96.18 | O13: 45834 | P13: Kalunga | Q13: 16.8 | R13: 45862 | S13: Serra | T13: 18
I14: 45769 | J14: Marechal | K14: =30+75.08 -> 105.08 | O14: 45835 | P14: Loterica | Q14: 69.82 | R14: 45868 | S14: Japao | T14: 36.9
A15: Saldo | B15: 30.71 | I15: 45769 | J15: Almoco | K15: 96.4 | O15: 45835 | P15: France Car (1/4) | Q15: =830/4 -> 207.5 | R15: 45868 | S15: Pastel | T15: 29
A16: Transferir | B16: =B13-B15 -> -30.71 | I16: 45767 | J16: Camila Bastos | K16: 99 | O16: 45835 | P16: Animais pet | Q16: 15.9 | R16: 45862 | S16: Posto | T16: 224
I17: 45767 | J17: Delicias da barra | K17: 59.9 | O17: =O15 -> 45835 | P17: PROTECAO OURO | Q17: 3 | R17: 45870 | S17: Burguer | T17: 111.4
I18: 45767 | J18: Sorvete | K18: 25.5 | O18: 45835 | P18: Uber | Q18: =25.97+11.99+21.94+16.98+8.93+43.99+34.95 -> 164.75 | R18: 45870 | S18: Drogaria | T18: 34
I19: 45766 | J19: Hudson | K19: 13.6 | O19: 45836 | P19: Novo Espaço | Q19: 39.9 | R19: 45869 | S19: Posto | T19: 100
I20: 45769 | J20: Marechal | K20: 30 | O20: 45837 | P20: Vila Carioca | Q20: 109.41 | R20: 45868 | S20: Japao | T20: 36.9
I21: 45775 | J21: Sorvete | K21: 65.9 | O21: 45837 | P21: Drogaria | Q21: 32.39 | R21: 45867 | S21: Drogaria (1/3) | T21: =407.37/3 -> 135.79
I22: 45775 | J22: Case mania(1/2) | K22: =150/2 -> 75 | O22: 45837 | P22: Posto | Q22: 100 | S22: uber | T22: 90
I23: 45775 | J23: Casa do pao | K23: 8 | O23: 45838 | P23: Almoço | Q23: 33 | R23: 45881 | S23: Posto | T23: 100
I24: 45775 | J24: Flor do nordeste | K24: 114 | O24: 45839 | P24: Casa das variedades | Q24: 139.9
I25: 45775 | J25: Praia | K25: 68.2
I26: 45774 | J26: Praia -0 luciano | K26: 81.4
I27: 45773 | J27: Barrada da vera | K27: 66.1
I28: 45773 | J28: Acaraje socorro | K28: =40+55 -> 95
I29: 45774 | J29: Barrada da vera | K29: 100.25
E30: =SUM(E2:E29) -> 669.58 | H30: =SUM(H2:H29) -> 172.8 | I30: 45770 | J30: Flip turismo | K30: 25 | N30: =SUM(N2:N29) -> 247.8 | Q30: =SUM(Q2:Q29) -> 1396.32 | T30: =SUM(T2:T29) -> 1897.39 | W30: =SUM(W2:W29) -> 736.29 | Z30: =SUM(Z2:Z29) -> 736.29 | AC30: =SUM(AC2:AC29) -> 83 | AF30: =SUM(AF2:AF29) -> 83 | AI30: =SUM(AI2:AI29) -> 83 | AL30: =SUM(AL2:AL29) -> 83
I31: 45772 | J31: Posto | K31: 50
I32: 45770 | J32: Sorvete | K32: 25.5
I33: 45772 | J33: Ilha do paraiso | K33: 67.5
I34: 45771 | J34: Unicompra | K34: 127.53
I35: 45770 | J35: Restaurante tropical | K35: 228
I36: 45776 | J36: Camila Bastos | K36: 116.6
I37: 45777 | J37: Stone | K37: 15
I38: 45777 | J38: C&A | K38: 119.98
I39: 45777 | J39: Barrada da vera | K39: 35.4
I40: 45777 | J40: Pirilampo | K40: 59.99
...

Sheet BB VISA 4356 - Vence dia 12 
A1: Item | B1: Valor | C1: 45748 | F1: =C1+31 -> 45779 | I1: =F1+31 -> 45810 | L1: =I1+31 -> 45841 | O1: =L1+31 -> 45872 | R1: =O1+31 -> 45903 | U1: =R1+31 -> 45934 | X1: =U1+31 -> 45965 | AA1: =X1+31 -> 45996 | AD1: =AA1+31 -> 46027 | AG1: =AD1+31 -> 46058 | AJ1: =AG1+31 -> 46089 | AM1: =AJ1+31 -> 46120 | AP1: =AM1+31 -> 46151 | AS1: =AP1+31 -> 46182 | AV1: =AS1+31 -> 46213 | AY1: =AV1+31 -> 46244
A2: Condomínio | C2: Data | D2: Descrição | E2: Valor | F2: Data | G2: Descrição | H2: Valor | I2: Data | J2: Descrição | K2: Valor | L2: Data | M2: Descrição | N2: Valor | O2: Data | P2: Descrição | Q2: Valor | R2: Data | S2: Descrição | T2: Valor | U2: Data | V2: Descrição | W2: Valor | X2: Data | Y2: Descrição | Z2: Valor | AA2: Data | AB2: Descrição | AC2: Valor | AD2: Data | AE2: Descrição | AF2: Valor | AG2: Data | AH2: Descrição | AI2: Valor | AJ2: Data | AK2: Descrição | AL2: Valor | AM2: Data | AN2: Descrição | AO2: Valor | AP2: Data | AQ2: Descrição | AR2: Valor | AS2: Data | AT2: Descrição | AU2: Valor | AV2: Data | AW2: Descrição | AX2: Valor | AY2: Data | AZ2: Descrição | BA2: Valor
A3: Brasília | B3: 0 | C3: 83 | D3: Mesa Shoope (1/2) | E3: =156.65/2 -> 78.325 | F3: =F1 -> 45779 | G3: PROTECAO OURO | H3: 3 | I3: 45620 | J3: TAP - Tirza (7/9) | K3: =14819.24/9 -> 1646.5822 | L3: 45620 | M3: TAP - Tirza (8/9) | N3: =14819.24/9 -> 1646.5822 | O3: 45620 | P3: TAP - Tirza (9/9) | Q3: =14819.24/9 -> 1646.5822 | R3: =R1 -> 45903 | S3: PROTECAO OURO | T3: 3 | U3: =U1 -> 45934 | V3: PROTECAO OURO | W3: 3 | X3: =X1 -> 45965 | Y3: PROTECAO OURO | Z3: 3 | AA3: =AA1 -> 45996 | AB3: PROTECAO OURO | AC3: 3 | AD3: =AD1 -> 46027 | AE3: PROTECAO OURO | AF3: 3 | AG3: =AG1 -> 46058 | AH3: PROTECAO OURO | AI3: 3 | AJ3: =AJ1 -> 46089 | AK3: PROTECAO OURO | AL3: 3 | AM3: =AM1 -> 46120 | AN3: PROTECAO OURO | AO3: 3 | AP3: =AP1 -> 46151 | AQ3: PROTECAO OURO | AR3: 3 | AS3: =AS1 -> 46182 | AT3: PROTECAO OURO | AU3: 3 | AV3: =AV1 -> 46213 | AW3: PROTECAO OURO | AX3: 3 | AY3: =AY1 -> 46244 | AZ3: PROTECAO OURO | BA3: 3
A4: Caldas | B4: 0 | C4: 45620 | D4: TAP - Tirza (5/9) | E4: =14819.24/9 -> 1646.5822 | F4: 45620 | G4: TAP - Tirza (6/9) | H4: =14819.24/9 -> 1646.5822 | I4: 45756 | J4: Boticario (2/2) | K4: =274.7/2 -> 137.35 | L4: 45786 | M4: Paris joias (2/2) | N4: =230/2 -> 115 | O4: 45781 | P4: Relogio | Q4: 65 | R4: 45620 | S4: TAP - Tirza (9/9) | T4: =14819.24/9 -> 1646.5822 | U4: 45874 | V4: Claro (2/12) | W4: =1423.8/12 -> 118.65 | X4: 45874 | Y4: Claro (3/12) | Z4: =1423.8/12 -> 118.65 | AA4: 45874 | AB4: Claro (4/12) | AC4: =1423.8/12 -> 118.65 | AD4: 45874 | AE4: Claro (5/12) | AF4: =1423.8/12 -> 118.65 | AG4: 45874 | AH4: Claro (6/12) | AI4: =1423.8/12 -> 118.65 | AJ4: 45874 | AK4: Claro (7/12) | AL4: =1423.8/12 -> 118.65 | AM4: 45874 | AN4: Claro (8/12) | AO4: =1423.8/12 -> 118.65 | AP4: 45874 | AQ4: Claro (9/12) | AR4: =1423.8/12 -> 118.65 | AS4: 45874 | AT4: Claro (10/12) | AU4: =1423.8/12 -> 118.65 | AV4: 45874 | AW4: Claro (11/12) | AX4: =1423.8/12 -> 118.65 | AY4: 45874 | AZ4: Claro (12/12) | BA4: =1423.8/12 -> 118.65
A5: Cartão | C5: 45626 | D5: AP - Ana (4/4) | E5: =8109/4 -> 2027.25 | F5: 45626 | G5: AP - Ana (4/4) | H5: =8109/4 -> 2027.25 | I5: 45757 | J5: D. Bere (2/2) | K5: =158/2 -> 79 | L5: 45808 | M5: Brasal | N5: 100 | O5: 45841 | P5: Boticario | Q5: 123.18 | R5: 45870 | S5: Agropet | T5: 50 | U5: 45874 | V5: Oticas (2/2) | W5: =180/2 -> 90 | X5: 45872 | Y5: GadGlace(3/3) | Z5: =139.8/3 -> 46.6
A6: Capitalização | B6: 0 | C6: 45626 | D6: TAP - Rogerio (4/4) | E6: =7288.14/4 -> 1822.035 | F6: 45626 | G6: TAP - Rogerio (4/4) | H6: =7288.14/4 -> 1822.035 | I6: 45778 | J6: Villa niquim | K6: 117.7 | L6: 45808 | M6: casa de cachorro | N6: 35 | O6: 45841 | P6: Alm,oço | Q6: 25 | R6: 45871 | S6: Madstain | T6: 130 | U6: 45872 | V6: GadGlace(2/3) | W6: =139.8/3 -> 46.6
A7: Seguro | B7: 0 | C7: 45717 | D7: Mercado | E7: 32.97 | F7: 83 | G7: Mesa Shoope (1/2) | H7: =156.65/2 -> 78.325 | I7: 45778 | J7: Bruna | K7: 30.06 | L7: 45808 | M7: Drogasil | N7: 113.1 | O7: 45842 | P7: Gate store | Q7: 21.42 | R7: 45873 | S7: Pets | T7: 61.99
A8: Emprestimo | B8: 0 | C8: 45718 | D8: D. Xepa | E8: 109.89 | F8: 45726 | G8: Drogasil (1/2) | H8: =241.41/2 -> 120.705 | I8: 45778 | J8: Barraca da vera | K8: 37.38 | L8: 45810 | M8: Posto | N8: 136.65 | O8: 45842 | P8: Almoço | Q8: 39 | R8: 45873 | S8: Drogaria | T8: 90
A9: TED | B9: 0 | C9: 45721 | D9: Na vendinha | E9: 16.98 | F9: 45749 | G9: Burguer | H9: 70.1 | I9: 45779 | J9: Villa niquim | K9: 169.4 | L9: 45810 | M9: Cacique | N9: =13+4.5 -> 17.5 | O9: 45843 | P9: Drogaria | Q9: 114.43 | R9: 45872 | S9: Posto | T9: 229.45
A10: Mensalidade | B10: 0 | C10: 45721 | D10: Pirscila | E10: 30 | F10: 45756 | G10: Simone caldas | H10: 16 | I10: 45779 | J10: Barraca da vera | K10: 72.69 | L10: 45810 | M10: Infratech | N10: 157 | O10: 45843 | P10: Casa de cachorro | Q10: 40 | R10: 45872 | S10: Restaurante | T10: 48.3
A11: Tarifa de conta | B11: 0 | C11: 45721 | D11: Bonanza | E11: 29.14 | F11: 45757 | G11: Compra caldas | H11: 31 | I11: 45780 | J11: Barraca da vera | K11: 96.78 | L11: 45813 | M11: comercio | N11: 10 | O11: 45845 | P11: DR. Anmal | Q11: 35 | R11: 45876 | S11: Pastel | T11: 80
A12: Extra | B12: 0 | C12: 45722 | D12: Japão | E12: 26.9 | F12: 45756 | G12: D. Xepa | H12: 139.92 | I12: 45780 | J12: Posto | K12: 67.9 | L12: 45813 | M12: Cascol | N12: 120 | O12: 45846 | P12: Pastel | Q12: 29 | R12: 45874 | S12: Claro (1/12) | T12: =1423.8/12 -> 118.65
A13: Total | B13: =SUM(B2:B12) -> 0 | C13: 45723 | D13: Amo pastel | E13: 60 | F13: 45757 | G13: D. Bere (1/2) | H13: =158/2 -> 79 | I13: 45780 | J13: Bruna | K13: 46.26 | L13: 45813 | M13: Ygor | N13: 27 | O13: 45847 | P13: Patio | Q13: 18 | R13: 45878 | S13: Alvaro | T13: 40
C14: 45725 | D14: Bonanza | E14: 17.59 | F14: 45756 | G14: Kaely | H14: 55.23 | I14: 45781 | J14: Belavia | K14: 56.86 | L14: 45814 | M14: Hoopa fast food | N14: 25 | O14: 45847 | P14: Torteria | Q14: 7 | R14: 45877 | S14: Burguer | T14: 37
A15: Saldo | B15: 0 | C15: 45725 | D15: Ligeirinho | E15: 339.95 | F15: 45756 | G15: Village | H15: =20+50+21 -> 91 | I15: 45781 | J15: Bonanza | K15: 138.84 | L15: 45814 | M15: Rango de lei | N15: 77.8 | O15: =O13 -> 45847 | P15: PROTECAO OURO | Q15: 3 | R15: 45877 | S15: Claudio | T15: 50
A16: Transferir | B16: 0 | C16: 45725 | D16: Ultrabox | E16: 17.98 | F16: 45753 | G16: Feira do luar | H16: 20 | I16: 45782 | J16: Embalagens avenida | K16: 67.2 | L16: 45815 | M16: Novo espaço | N16: 57.09 | R16: 45876 | S16: Casa de cachorro | T16: 90
C17: 45725 | D17: Bonanza | E17: 36.52 | F17: 45752 | G17: Ivan cabeleleiro | H17: 30 | I17: 45782 | J17: Correios | K17: 99.6 | L17: 45815 | M17: casa de cachorro | N17: 35 | R17: 45876 | S17: Restaurante | T17: 42
C18: 45726 | D18: SESC | E18: 280 | F18: 45753 | G18: Dragaria | H18: 43.99 | I18: 45783 | J18: Arly | K18: 50 | L18: =L16 -> 45815 | M18: PROTECAO OURO | N18: 3 | R18: 45874 | S18: Estacionamento | T18: 18
C19: 45726 | D19: Drogasil (1/2) | E19: =241.41/2 -> 120.705 | F19: 45754 | G19: Assai | H19: 24.51 | I19: 45783 | J19: SESC | K19: 46.68 | L19: 45908 | M19: Tche picanha | N19: 77.01 | R19: 45874 | S19: Oticas (1/2) | T19: =180/2 -> 90
C20: 45726 | D20: Restarurante | E20: 15.54 | F20: 45752 | G20: Casa do adubo | H20: 66.5 | I20: 45784 | J20: Agropet | K20: 90 | L20: 45787 | M20: Da roça | N20: 12 | R20: 45872 | S20: Posto | T20: 53
C21: 45726 | D21: Posto | E21: 215.95 | F21: 45751 | G21: Posto | H21: 90.41 | I21: 45784 | J21: Japao | K21: 34.4 | L21: 45820 | M21: Da roça | N21: 25 | R21: 45872 | S21: GadGlace(1/3) | T21: =139.8/3 -> 46.6
C22: 45726 | D22: Bonanza | E22: 52.73 | F22: 45751 | G22: Posto | H22: 153.94 | I22: 45784 | J22: Bonanza | K22: 26.36 | L22: 45819 | M22: Assai | N22: 131.47
C23: =C21 -> 45726 | D23: PROTECAO OURO | E23: 3 | F23: 45750 | G23: Xeus | H23: 65 | I23: 45785 | J23: Japao | K23: 42.8 | L23: 45819 | M23: Leonidas | N23: 16
E24: 100 | F24: 45751 | G24: Entre trevos | H24: 57.92 | I24: 45785 | J24: Bonanza | K24: 26.65 | L24: 45817 | M24: Posto | N24: 244.2
F25: 45752 | G25: Assai | H25: 102.32 | I25: 45786 | J25: Padaria | K25: 17.97 | L25: 45817 | M25: Liliany | N25: 19
F26: 45752 | G26: D.Xepa | H26: 40.51 | I26: 45786 | J26: Drogaria | K26: 23.76
F27: 45756 | G27: Boticario (1/2) | H27: =274.7/2 -> 137.35 | I27: 45786 | J27: Debora | K27: 80
H28: 300 | I28: 45786 | J28: Drogaria | K28: 29.59
E29: =SUM(E2:E28) -> 7080.0372 | H29: =SUM(H2:H28) -> 7312.5972 | I29: 45786 | J29: Paris joias (1/2) | K29: =230/2 -> 115 | N29: =SUM(N2:N28) -> 3200.4022 | Q29: =SUM(Q2:Q28) -> 2166.6122 | T29: =SUM(T2:T28) -> 2924.5722 | W29: =SUM(W2:W28) -> 258.25 | Z29: =SUM(Z2:Z28) -> 168.25 | AC29: =SUM(AC2:AC28) -> 121.65 | AF29: =SUM(AF2:AF28) -> 121.65 | AI29: =SUM(AI2:AI28) -> 121.65 | AL29: =SUM(AL2:AL28) -> 121.65 | AO29: =SUM(AO2:AO28) -> 121.65 | AR29: =SUM(AR2:AR28) -> 121.65 | AU29: =SUM(AU2:AU28) -> 121.65 | AX29: =SUM(AX2:AX28) -> 121.65 | BA29: =SUM(BA2:BA28) -> 121.65
I30: 45786 | J30: Eu amo pastel | K30: 67.5
I31: =I29 -> 45786 | J31: PROTECAO OURO | K31: 3
I32: 45786 | J32: Posto | K32: =222.13+220.94 -> 443.07
I33: 45786 | J33: ABBA | K33: 295.8
K36: =SUM(K2:K35) -> 4256.1822

Sheet Santander 9674 Vende dia 22
A1: Item | B1: Valor | C1: 45748 | F1: =C1+31 -> 45779 | I1: =F1+31 -> 45810 | L1: =I1+31 -> 45841 | O1: =L1+31 -> 45872 | R1: =O1+31 -> 45903 | U1: =R1+31 -> 45934 | X1: =U1+31 -> 45965 | AA1: =X1+31 -> 45996 | AD1: =AA1+31 -> 46027 | AG1: =AD1+31 -> 46058 | AJ1: =AG1+31 -> 46089
A2: Condomínio | C2: Data | D2: Descrição | E2: Valor | F2: Data | G2: Descrição | H2: Valor | I2: Data | J2: Descrição | K2: Valor | L2: Data | M2: Descrição | N2: Valor | O2: Data | P2: Descrição | Q2: Valor | R2: Data | S2: Descrição | T2: Valor | U2: Data | V2: Descrição | W2: Valor | X2: Data | Y2: Descrição | Z2: Valor | AA2: Data | AB2: Descrição | AC2: Valor | AD2: Data | AE2: Descrição | AF2: Valor | AG2: Data | AH2: Descrição | AI2: Valor | AJ2: Data | AK2: Descrição | AL2: Valor
A3: Brasília | B3: 0 | C3: 42621 | D3: Anuidade (12/12) | E3: 46.5 | F3: 42621 | G3: Anuidade (12/12) | H3: 46.5 | I3: 42621 | J3: Anuidade (12/12) | K3: 46.5 | L3: 42621 | M3: Anuidade (12/12) | N3: 46.5 | O3: 42621 | P3: Anuidade (12/12) | Q3: 46.5 | R3: 42621 | S3: Anuidade (12/12) | T3: 46.5 | U3: 42621 | V3: Anuidade (12/12) | W3: 46.5 | X3: 42621 | Y3: Anuidade (12/12) | Z3: 46.5 | AA3: 42621 | AB3: Anuidade (12/12) | AC3: 46.5 | AD3: 42621 | AE3: Anuidade (12/12) | AF3: 46.5 | AG3: 42621 | AH3: Anuidade (12/12) | AI3: 46.5 | AJ3: 42621 | AK3: Anuidade (12/12) | AL3: 46.5
A4: Caldas | B4: 0 | C4: 45647 | D4: Imperio bombas (4/6) | E4: =4951/6 -> 825.16667 | F4: 45647 | G4: Imperio bombas (5/6) | H4: =4951/6 -> 825.16667 | I4: 45647 | J4: Imperio bombas (6/6) | K4: =4951/6 -> 825.16667 | L4: 45706 | M4: Club Diamond (6/8) | N4: 82.38 | O4: 45677 | P4: Hote lromenia | Q4: 1000 | R4: 45706 | S4: Club Diamond (8/8) | T4: 82.38 | U4: 45726 | V4: HBO MAX (10/12) | W4: 18.9 | X4: 45726 | Y4: HBO MAX (11/12) | Z4: 18.9 | AA4: 45726 | AB4: HBO MAX (12/12) | AC4: 18.9
A5: Cartão Santander | B5: 2070 | C5: 45492 | D5: Seguro Tiggo (9/10) | E5: =241.9 -> 241.9 | F5: 45492 | G5: Seguro Tiggo (10/10) | H5: =241.9 -> 241.9 | I5: 45706 | J5: Club Diamond (5/8) | K5: 82.38 | L5: 45793 | M5: Convert (2/2) | N5: =940.69/2 -> 470.345 | O5: 45706 | P5: Club Diamond (7/8) | Q5: 82.38 | R5: 45726 | S5: HBO MAX (9/12) | T5: 18.9
A6: Capitalização | B6: 20 | C6: 45706 | D6: Japao (2/2) | E6: 119.65 | F6: 45706 | G6: Club Diamond (4/8) | H6: 82.38 | I6: 45746 | J6: Drogaria(3/3) | K6: =234.3/3 -> 78.1 | L6: 45848 | M6: Fonte Note | N6: 63.91 | O6: 45854 | P6: Echo pop | Q6: 269
A7: Seguro | B7: 0 | C7: 45706 | D7: Club Diamond (3/8) | E7: 82.38 | F7: 45736 | G7: (japao 1/2) | H7: =290/2 -> 145 | I7: 45793 | J7: Convert (1/2) | K7: =940.69/2 -> 470.345 | L7: 45841 | M7: Ilhas berlengas | N7: 1433.21 | O7: 45726 | P7: HBO MAX (8/12) | Q7: 18.9
A8: Emprestimo | B8: 0 | C8: 45739 | D8: Drogasil | E8: 44.24 | F8: 45746 | G8: Drogaria(2/3) | H8: =234.3/3 -> 78.1 | I8: 45796 | J8: Almoço | K8: 80 | L8: 45726 | M8: HBO MAX (7/12) | N8: 18.9 | O8: 45859 | P8: Lima Vill | Q8: 10
A9: TED | B9: 0 | C9: 45737 | D9: Festa | E9: 79.8 | F9: 45783 | G9: Cesta | H9: 243 | I9: 45796 | J9: Posto | K9: 100 | Q9: 300
A10: Capitalização | B10: 0 | C10: 45739 | D10: Gela guela | E10: 19.78 | I10: 45796 | J10: Casa de cachorro | K10: 35
A11: Tarifa de conta | B11: 21 | C11: 45738 | D11: Bonanza | E11: 270 | I11: 45799 | J11: Sabor cerrado | K11: 63
A12: Extra | B12: 10 | C12: 45737 | D12: Bonanza | E12: 18.7 | I12: 45798 | J12: Corte | K12: 30
A13: Total | B13: =SUM(B3:B12) -> 2121 | C13: 45737 | D13: Ultrabox | E13: 6.89 | I13: 45797 | J13: Carro de boi | K13: 81
C14: 45735 | D14: Monica | E14: 50 | I14: 45797 | J14: Posto Calcas | K14: 212.56
A15: Saldo | B15: 2252.23 | C15: 45735 | E15: 27.18 | I15: 45798 | J15: Assai | K15: 90.28
A16: Aplicação | B16: 0 | C16: 45737 | D16: Ultrabox | E16: 23.38
A17: Transferir | B17: =B13-B15 -> -131.23 | C17: 45736 | D17: (Japao 1/2) Material Tamila | E17: =290/2 -> 145
C18: 45737 | D18: Burguer | E18: 211.2
C19: 45741 | D19: Almoço | E19: 80
C20: 45743 | D20: Eletrica | E20: 50
C21: 45742 | D21: Fazendinha | E21: 129.36
C22: 45743 | D22: Ultrabox | E22: 113.74
C23: 45743 | D23: Drogaria | E23: 29.99
C24: 45748 | D24: Romao | E24: 370
C25: 45746 | D25: Drogaria(1/3) | E25: =234.3/3 -> 78.1
C26: 45743 | D26: Drogaria | E26: 33.36
C27: 45745 | D27: Drogaria | E27: 141.4
C28: 45748 | D28: Aero | E28: 24
E29: =SUM(E3:E28) -> 3261.7167 | H29: =SUM(H3:H28) -> 1662.0467 | K29: =SUM(K3:K28) -> 2194.3317 | N29: =SUM(N3:N28) -> 2115.245 | Q29: =SUM(Q3:Q28) -> 1726.78 | T29: =SUM(T3:T28) -> 147.78 | W29: =SUM(W3:W28) -> 65.4 | Z29: =SUM(Z3:Z28) -> 65.4 | AC29: =SUM(AC3:AC28) -> 65.4 | AF29: =SUM(AF3:AF28) -> 46.5 | AI29: =SUM(AI3:AI28) -> 46.5 | AL29: =SUM(AL3:AL28) -> 46.5

Sheet BB Petrobras 8392 Vence dia 22
A1: Item | B1: Valor | C1: 45748 | F1: =C1+31 -> 45779 | I1: =F1+31 -> 45810 | L1: =I1+31 -> 45841 | O1: =L1+31 -> 45872 | R1: =O1+31 -> 45903 | U1: =R1+31 -> 45934 | X1: =U1+31 -> 45965 | AA1: =X1+31 -> 45996 | AD1: =AA1+31 -> 46027 | AG1: =AD1+31 -> 46058 | AJ1: =AG1+31 -> 46089
A2: Condomínio | C2: Data | D2: Descrição | E2: Valor | F2: Data | G2: Descrição | H2: Valor | I2: Data | J2: Descrição | K2: Valor | L2: Data | M2: Descrição | N2: Valor | O2: Data | P2: Descrição | Q2: Valor | R2: Data | S2: Descrição | T2: Valor | U2: Data | V2: Descrição | W2: Valor | X2: Data | Y2: Descrição | Z2: Valor | AA2: Data | AB2: Descrição | AC2: Valor | AD2: Data | AE2: Descrição | AF2: Valor | AG2: Data | AH2: Descrição | AI2: Valor | AJ2: Data | AK2: Descrição | AL2: Valor
A3: Brasília | B3: 0 | C3: =C1 -> 45748 | D3: PROTECAO OURO | E3: 6 | F3: =F1 -> 45779 | G3: PROTECAO OURO | H3: 6 | I3: =I1 -> 45810 | J3: PROTECAO OURO | K3: 6 | L3: =L1 -> 45841 | M3: PROTECAO OURO | N3: 6 | O3: 45595 | P3: Google | Q3: 7.99 | R3: =R1 -> 45903 | S3: PROTECAO OURO | T3: 6 | U3: =U1 -> 45934 | V3: PROTECAO OURO | W3: 6 | X3: =X1 -> 45965 | Y3: PROTECAO OURO | Z3: 6 | AA3: =AA1 -> 45996 | AB3: PROTECAO OURO | AC3: 6 | AD3: =AD1 -> 46027 | AE3: PROTECAO OURO | AF3: 6 | AG3: =AG1 -> 46058 | AH3: PROTECAO OURO | AI3: 6 | AJ3: =AJ1 -> 46089 | AK3: PROTECAO OURO | AL3: 6
A4: Caldas | B4: 0 | C4: 45595 | D4: Google | E4: 7.99 | F4: 45595 | G4: Google | H4: 7.99 | I4: 45595 | J4: Google | K4: 7.99 | L4: 45595 | M4: Google | N4: 7.99 | O4: 45793 | P4: Home cell (3/6) | Q4: =600/6 -> 100 | R4: 45595 | S4: Google | T4: 7.99 | U4: 45595 | V4: Google | W4: 7.99 | X4: 45595 | Y4: Google | Z4: 7.99 | AA4: 45595 | AB4: Google | AC4: 7.99 | AD4: 45595 | AE4: Google | AF4: 7.99 | AG4: 45595 | AH4: Google | AI4: 7.99 | AJ4: 45595 | AK4: Google | AL4: 7.99
A5: Cartão | C5: 45699 | D5: Shoope Gatoeria (1/2) | E5: 126.33 | F5: 45788 | G5: Decolar Maceio (3/4) | H5: =5335.31/4 -> 1333.8275 | I5: 45788 | J5: Decolar Maceio (4/4) | K5: =5335.31/4 -> 1333.8275 | L5: 45793 | M5: Home cell (2/6) | N5: =600/6 -> 100 | O5: 45840 | P5: Irmaõ abe | Q5: 38 | R5: 45793 | S5: Home cell (4/6) | T5: =600/6 -> 100 | U5: 45793 | V5: Home cell (5/6) | W5: =600/6 -> 100 | X5: 45793 | Y5: Home cell (6/6) | Z5: =600/6 -> 100
A6: Capitalização | B6: 0 | C6: 45788 | D6: Decolar Maceio (2/4) | E6: =5335.31/4 -> 1333.8275 | F6: 45707 | G6: Castelo forte (3/4) | H6: =212.28/4 -> 53.07 | I6: 45707 | J6: Castelo forte (4/4) | K6: =212.28/4 -> 53.07 | L6: 45820 | M6: Pelicula celular | N6: 50 | O6: 45840 | P6: Japão | Q6: 23.9 | R6: 45881 | S6: Cantinho da jo | T6: 20 | U6: 45882 | V6: Fontes(2/3) | W6: =240/3 -> 80 | X6: 45882 | Y6: Fontes(3/3) | Z6: =240/3 -> 80
A7: Seguro | B7: 0 | C7: 45707 | D7: Castelo forte (2/4) | E7: =212.28/4 -> 53.07 | F7: 45759 | G7: Posto | H7: 144.98 | I7: 45761 | J7: Decathlon (2/2) | K7: =179.98/2 -> 89.99 | L7: 45820 | M7: King don | N7: 38 | O7: 45849 | P7: Eu amo pastel | Q7: =29.5+40 -> 69.5 | R7: 45882 | S7: Fontes(1/3) | T7: =240/3 -> 80
A8: Emprestimo | B8: 0 | C8: 45700 | D8: Localiza | E8: 1287.16 | F8: 45758 | G8: Dalac | H8: 94.88 | I8: 45788 | J8: Gaviao | K8: 56.11 | L8: 45820 | M8: Assai | N8: 56.4 | O8: 45850 | P8: Estacionamento | Q8: 14 | R8: 45881 | S8: Impressao | T8: 57
A9: TED | B9: 0 | C9: 45727 | D9: Belissima | E9: 18.58 | F9: 45759 | G9: Posto | H9: 156.3 | I9: 45793 | J9: Home cell (1/6) | K9: =600/6 -> 100 | L9: 45822 | M9: Cantinho do caldo | N9: 24 | O9: 45850 | P9: Pastelaira | Q9: =39+17 -> 56 | R9: 45882 | S9: Goiano | T9: 66.66
A10: Mensalidade | B10: 0 | C10: 45727 | D10: Seu joaca | E10: 147.2 | F10: 45760 | G10: Drogacenter | H10: 16.76 | I10: 45793 | J10: Almoço | K10: 67.3 | L10: 45827 | M10: Vips bar | N10: 116.58 | O10: 45850 | P10: Hamburguer | Q10: 31.9 | R10: 45881 | S10: TNF | T10: 30
A11: Tarifa de conta | B11: 0 | C11: 45728 | D11: Almoço | E11: 74 | F11: 45760 | G11: Atendelar | H11: 86.44 | I11: 45793 | J11: Drogaria | K11: 8.99 | L11: 45829 | M11: Drogaria | N11: 6.5 | O11: 45851 | P11: Informal | Q11: 8 | R11: 45881 | S11: TNF | T11: 70
A12: Extra | B12: 0 | C12: 45727 | D12: Drogaria | E12: 105 | F12: 45760 | G12: Drogaria | H12: 37.98 | I12: 45794 | J12: Seu joaca | K12: 75.6 | L12: 45826 | M12: Eletrica volts | N12: 50 | O12: 45851 | P12: Laser (mercadolivre) | Q12: 47.88 | R12: 45881 | S12: Drogaria | T12: 50.09
A13: Total | B13: =SUM(B2:B12) -> 0 | C13: 45727 | D13: Bonanza | E13: 41.74 | F13: 45761 | G13: SESC | H13: 285.98 | I13: 45794 | J13: Caju limão | K13: 298.92 | L13: 45825 | M13: Posto | N13: 132.34 | O13: 45852 | P13: Casa de cachorro | Q13: 40
C14: 45727 | D14: SESC | E14: 60 | F14: 45761 | G14: Almoço | H14: 145 | I14: 45794 | J14: Agropet | K14: 18 | L14: 45825 | M14: Posto | N14: 149.18 | O14: 45852 | P14: Marmita | Q14: 23
A15: Saldo | B15: 0 | C15: 45733 | D15: Dia a dia | E15: 66.33 | F15: 45761 | G15: Mega cartuchos | H15: 25 | I15: 45793 | J15: Home cell (1/6) | K15: =600/6 -> 100 | L15: 45826 | M15: Seu joaca | N15: 70 | O15: 45852 | P15: Don albertus | Q15: 96.5
A16: Transferir | B16: =B13-B15 -> 0 | C16: 45732 | D16: Joaca | E16: 205 | F16: 45761 | G16: Coffe | H16: 29.5 | I16: 45795 | J16: Venda | K16: 112 | L16: 45821 | M16: Cleiton Wagner | N16: 15 | O16: 45853 | P16: Posto | Q16: 148.19
C17: 45732 | D17: Supera food | E17: 4.5 | F17: 45761 | G17: Decathlon (1/2) | H17: =179.98/2 -> 89.99 | I17: 45793 | J17: Cafeteria | K17: 44.77 | L17: 45820 | M17: Restaurante Café da Roça | N17: 25 | O17: 45853 | P17: Posto | Q17: 179.06
C18: 45736 | D18: Supera food | E18: 105 | F18: 45764 | G18: Posto | H18: 100 | I18: 45791 | J18: Lanche | K18: 70.57 | L18: 45841 | M18: Grelha | N18: 95 | O18: 45853 | P18: Almoco | Q18: 29
C19: 45732 | D19: Ultrabox | E19: 49.61 | F19: 45764 | G19: Novo espaço | H19: 50 | I19: 45803 | J19: Ifoof | K19: 72 | O19: 45854 | P19: Simone | Q19: 26
C20: 45733 | D20: SESC | E20: 11.98 | F20: 45763 | G20: Drogaria | H20: 131.67 | I20: 45799 | J20: Preco único | K20: 198 | O20: 45854 | P20: Comercial Silva | Q20: 164
C21: 45731 | D21: Japao | E21: 39.9 | F21: 45763 | G21: Xeus | H21: 110 | O21: 45855 | P21: Tassara | Q21: 20
C22: 45730 | D22: Casa de cachorro | E22: 50 | O22: 45856 | P22: Acai Point | Q22: 9.79
C23: 45729 | D23: Bonanza | E23: 54.14 | O23: 45857 | P23: Loja por do sol | Q23: 15
C24: 45730 | D24: Outback | E24: 97.22 | O24: 45857 | P24: Mercado | Q24: 14.46
C25: 45729 | D25: Ultrabox | E25: 85.84 | O25: 45857 | P25: Tassara | Q25: 15
C26: 45732 | D26: Giraffa | E26: 88 | O26: 45857 | P26: Pastelaira | Q26: 14.5
O27: =O25 -> 45857 | P27: PROTECAO OURO | Q27: 6
O28: 45878 | P28: Novo espaço | Q28: 60.46
O29: 45878 | P29: CBS comercio | Q29: 155
E31: =SUM(E2:E30) -> 4118.4175 | H31: =SUM(H2:H30) -> 2905.3675 | K31: =SUM(K2:K30) -> 2713.1375 | N31: =SUM(N2:N30) -> 941.99 | Q31: =SUM(Q2:Q30) -> 1413.13 | T31: =SUM(T2:T30) -> 487.74 | W31: =SUM(W2:W30) -> 193.99 | Z31: =SUM(Z2:Z30) -> 193.99 | AC31: =SUM(AC2:AC30) -> 13.99 | AF31: =SUM(AF2:AF30) -> 13.99 | AI31: =SUM(AI2:AI30) -> 13.99 | AL31: =SUM(AL2:AL30) -> 13.99
